Workbook
Name _Toc184524643: Header!#REF!
Name a: #REF!
Name a: #REF!
Name a: #REF!
Name a: #REF!
Name a: #REF!
Name Client: #REF!
Name Client: #REF!
Name Client: #REF!
Name Client: #REF!
Name Client: 'PL-3-26 to 2-26'!$Q$2
Name Client: 'PL-3-26 to 4-35'!$Q$2
Name Client: 'Verifications-3-26 to 2-26'!$V$2
Name Client: 'Verifications-3-26 to 4-35'!$Q$2
Name Client: #REF!
Name Client1: #REF!
Name Client1: #REF!
Name Client1: #REF!
Name Client1: #REF!
Name Client1: #REF!
Name Location: #REF!
Name Location: #REF!
Name Location: #REF!
Name Location: #REF!
Name Location: 'PL-3-26 to 2-26'!$Q$3
Name Location: 'PL-3-26 to 4-35'!$Q$3
Name Location: 'Verifications-3-26 to 2-26'!$V$3
Name Location: 'Verifications-3-26 to 4-35'!$Q$3
Name Location: #REF!
Name Location1: #REF!
Name Location1: #REF!
Name Location1: #REF!
Name Location1: #REF!
Name Location1: #REF!
Name PipelineName: #REF!
Name PipelineName: #REF!
Name PipelineName: #REF!
Name PipelineName: #REF!
Name PipelineName: 'PL-3-26 to 2-26'!$C$3
Name PipelineName: 'PL-3-26 to 4-35'!$C$3
Name PipelineName: 'Verifications-3-26 to 2-26'!$C$3
Name PipelineName: 'Verifications-3-26 to 4-35'!$C$3
Name PipelineName: #REF!
Name PipelineName1: #REF!
Name PipelineName1: #REF!
Name PipelineName1: #REF!
Name PipelineName1: #REF!
Name PipelineName1: #REF!
Name PrintDate: #REF!
Name PrintDate: #REF!
Name PrintDate: #REF!
Name PrintDate: #REF!
Name PrintDate: 'PL-3-26 to 2-26'!$Q$4
Name PrintDate: 'PL-3-26 to 4-35'!$Q$4
Name PrintDate: 'Verifications-3-26 to 2-26'!$V$4
Name PrintDate: 'Verifications-3-26 to 4-35'!$Q$4
Name PrintDate: #REF!
Name PrintDate1: #REF!
Name PrintDate1: #REF!
Name PrintDate1: #REF!

Sheet Header
B1: Tethered Inspection Final Report
B3: Company | C3: ARC Resources | G3: Onstream Reference | H3: 180728-RL-T6A-A
B4: Line Name | C4: 4-35-68-25W5 to 2-26-68-25W5 | G4: Run Date | H4: 43310
B5: Location | C5: Valleyview , AB | G5: Onstream Field Sup. | H5: Rod Lussier
B6: License Number | C6: 28312-6 | G6: Diameter | H6: 168.3 mm
B7: Line Segment A | C7: 3-26-68-25W5 to 4-35-68-25W5 | G7: Pipeline Product | H7: Natural Gas
B8: Line Segment B | C8: 3-26-68-25W5 to 2-26-68-25W5 | G8: Wall Thickness | H8: 3.96 mm
B9: Line Segment C | C9: N/A | G9: Pipe Grade | H9: 290.1 MPa
B10: Field Name | C10: N/A | G10: Year of Construction | H10: XXXX
B11: Office Contact | C11: Norm Rief | G11: MOP | H11: 9930 kPa
B12: Inspector | C12: Norm Rief | G12: Analyst | H12: Ben Du/Warren Matthie /Keith Walters
B16: Inspection Summary
B18: Total Girth Welds | C18: 153 | G18: B31G Criteria | H18: Modified
B19: Total Valves | C19: 0 | G19: Interaction Rule | H19: 3t x 3t
B20: Total Metal Gains | C20: 1 | G20: Design Factor | H20: 1
B21: Total Casings | C21: 0 | G21: Largest Wall Loss(%) | H21: 0.8
B22: Total Tees/Tie-ins | C22: 0 | G22: Total ML Features | H22: 212
B23: Total Repairs | C23: 0 | G23: Total Clusters | H23: 8
B24: Length | C24: 2.772 km | G24: Total Effecting MOP | H24: 0
C26: The Google Earth Maps in this report are images supplied from Google Earth. They are a best effort to map
C27: the pipeline right of way. They should not be used for accurate pipeline measurements.
B29: Notes: | C29: Analysis of the inspection data has reported a total of 212 metal loss features with the deepest predicted wall loss sized at 80%. A 3t x 3t (t = wall thickness) defect interaction rule has been applied to the metal loss features for the purpose of Modified B31G failure pressure calculations. None of the metal loss or metal loss cluster feature's predicted failure pressure affects the current MAOP of the pipeline. Indications of metal loss features have been identified in close proximity to the girth welds. A comment stating “Associated with the Girth Weld” has been added to the Notes column to identify these indications. Due to the proximity of these metal loss indications to the girth weld, the features magnetic signature and sizing can potentially be affected.
C38: Onstream can pit gauge verify the metal losses from verification digs on a limited basis. The verification of the pipeline samples does not include cutting, cleaning or coating removal of the samples. Onstream does not have the facilities, equipment or personnel to safely prepare the pipe for verification. If the pipeline samples are not properly prepared Onstream will send the pipe samples to a third party vendor which will incur additional costs to client and delays in report production. We also request the samples be sent in reasonable lengths, no longer than 2.0 meters and only the sections of pipe that have measurable metal losses need be provided. If you wish to send us pipe for verification please contact us prior to shipping so we may provide information on the pipe required, pipe preparation procedures and any charges which may be apply. If laser scanning of the features to determine pit depths and dimensions is required, additional costs to the client will be charged.
C42: This report has been specifically prepared for ARC Resources . Information provided in this report represents Onstream Pipeline Inspection Services’ (Onstream) interpretation of the pipeline inspection data gathered and shall not be construed as a warranty or Guarantee of the structural condition of the pipeline. Judgements concerning pipe condition and fitness for service are left entirely to ARC Resources . This report is strictly confidential and is to be used exclusively by ARC Resources . Under no circumstances should this report or information contained therein be distributed, reprinted or reproduced in any form without the written consent

Sheet PL-3-26 to 4-35
A1: Pipeline Listing
A2: Project No: | C2: 180728-RL-T6A-A | H2: Client: | I2: ARC Resources
A3: Pipeline Name: | C3: 4-35-68-25W5 to 2-26-68-25W5 | H3: Location: | I3: ValleyviewAB / Ante Creek (3-26-68-25W5 B/H to 4-35-68-25W5 Riser) | AE3: Imported: | AF3: P:\Data\ARC Resources\2018\Valleyview\180729-RL-T6A- 3-26 to 4-35 (28312-6)\180729-RL-T6A -A- 3-26 to 4-35\Documents\Re-Grade\180729-RL-T6A-A_PipelineListing.csv
A4: Run Date: | C4: 43310 | H4: Pipeline Segment: | I4: 3-26-68-25W5 to 4-35-68-25W5_Lic_28312-6 | Y4: Features: | Z4: 125
Y5: Joints: | Z5: 100
A6: Joint Number | B6: Feature Number | C6: Cluster Number | D6: Feature Type | E6: Distance (m) | F6: Joint Length (m) | G6: Dist to US Girth Weld (m) | H6: Dist to DS Girth Weld (m) | I6: Length (mm) | J6: Width (mm) | K6: Depth (%) | L6: Depth Measured (%) | M6: Depth Measured (mm) | N6: Difference Pred.-Meas. (%) | O6: Length Measured (mm) | P6: Width Measured (mm) | Q6: Int/Ext | R6: Estimated Repair Factor (ERF) | S6: Burst Pressure (kPa) | T6: Wall Thick (mm) | U6: Clock Position (hrs:min) | V6: % of OD Restriction | W6: Latitude (Dec Deg.) | X6: Longitude (Dec Deg.) | Y6: Elevation (m) | Z6: US Girth Weld to US Marker (m) | AA6: US Girth Weld to DS Marker (m) | AB6: Notes
A7: 1 | D7: Joint | E7: 0 | F7: 15.426 | T7: 3.96 | Z7: 0 | AA7: 799.962
A8: 1 | B8: 1 | D8: Flange | E8: 0 | F8: 15.426 | G8: 0 | H8: 15.426 | T8: 3.96 | W8: 54.911552 | X8: 117.70618 | Y8: 0 | Z8: 0 | AA8: 799.962 | AB8: Launch @ 3-26 to 4-35
A9: 1 | B9: 2 | D9: Other Installation | E9: 1.536 | F9: 15.426 | G9: 1.536 | H9: 13.89 | T9: 3.96 | Z9: 0 | AA9: 799.962 | AB9: Temporary Magnet at 12: 00
A10: 2 | D10: Joint | E10: 15.426 | F10: 7.714 | T10: 3.96 | Z10: 15.426 | AA10: 784.535
A11: 3 | D11: Joint | E11: 23.14 | F11: 16.252 | T11: 3.96 | Z11: 23.14 | AA11: 776.822
A12: 4 | D12: Joint | E12: 39.392 | F12: 18.894 | T12: 3.96 | Z12: 39.392 | AA12: 760.569
A13: 5 | D13: Joint | E13: 58.286 | F13: 18.884 | T13: 3.96 | Z13: 58.286 | AA13: 741.676
A14: 5 | B14: 3 | D14: Metal Loss | E14: 61.988 | F14: 18.884 | G14: 3.702 | H14: 15.182 | I14: 8 | J14: 10 | K14: 0.31 | L14: 0 | Q14: Internal | R14: 0.594 | S14: 16723.9 | T14: 3.96 | U14: 0.2375 | Z14: 58.286 | AA14: 741.676
A15: 5 | B15: 4 | D15: Metal Loss | E15: 62.092 | F15: 18.884 | G15: 3.806 | H15: 15.078 | I15: 14 | J15: 10 | K15: 0.32 | L15: 0 | Q15: Internal | R15: 0.606 | S15: 16399.6 | T15: 3.96 | U15: 0.2375 | Z15: 58.286 | AA15: 741.676
A16: 5 | B16: 5 | D16: Metal Loss | E16: 65.226 | F16: 18.884 | G16: 6.94 | H16: 11.944 | I16: 10 | J16: 10 | K16: 0.32 | L16: 0 | Q16: Internal | R16: 0.597 | S16: 16623.3 | T16: 3.96 | U16: 0.21527778 | Z16: 58.286 | AA16: 741.676
A17: 5 | B17: 6 | C17: 7 | D17: Metal Loss | E17: 73.739 | F17: 18.884 | G17: 15.453 | H17: 3.431 | I17: 8 | J17: 8 | K17: 0.34 | L17: 0 | Q17: Internal | R17: 0.595 | S17: 16700.7 | T17: 3.96 | U17: 0.20902778 | Z17: 58.286 | AA17: 741.676
A18: 5 | B18: 7 | D18: Cluster | E18: 73.748 | F18: 18.884 | G18: 15.462 | H18: 3.422 | I18: 25.9 | J18: 10.8612 | K18: 0.42 | L18: 0 | Q18: Internal | R18: 0.658 | S18: 15084.8 | T18: 3.96 | U18: 0.20763889 | Z18: 58.286 | AA18: 741.676
A19: 5 | B19: 8 | C19: 7 | D19: Metal Loss | E19: 73.757 | F19: 18.884 | G19: 15.471 | H19: 3.413 | I19: 8 | J19: 10 | K19: 0.42 | L19: 0 | Q19: Internal | R19: 0.597 | S19: 16630.3 | T19: 3.96 | U19: 0.20694444 | Z19: 58.286 | AA19: 741.676
A20: 6 | D20: Joint | E20: 77.17 | F20: 18.886 | T20: 3.96 | Z20: 77.17 | AA20: 722.792
A21: 7 | D21: Joint | E21: 96.056 | F21: 18.892 | T21: 3.96 | Z21: 96.056 | AA21: 703.905
A22: 8 | D22: Joint | E22: 114.948 | F22: 18.878 | T22: 3.96 | Z22: 114.948 | AA22: 685.014
A23: 9 | D23: Joint | E23: 133.826 | F23: 18.92 | T23: 3.96 | Z23: 133.826 | AA23: 666.135
A24: 9 | B24: 9 | D24: Metal Loss | E24: 136.544 | F24: 18.92 | G24: 2.718 | H24: 16.202 | I24: 4 | J24: 8 | K24: 0.39 | L24: 0 | Q24: Internal | R24: 0.59 | S24: 16834.2 | T24: 3.96 | U24: 0.38125 | Z24: 133.826 | AA24: 666.135
A25: 9 | B25: 10 | D25: Metal Loss | E25: 136.772 | F25: 18.92 | G25: 2.946 | H25: 15.974 | I25: 8 | J25: 6 | K25: 0.27 | L25: 0 | Q25: Internal | R25: 0.593 | S25: 16752.6 | T25: 3.96 | U25: 0.36111111 | Z25: 133.826 | AA25: 666.135
A26: 9 | B26: 11 | D26: Metal Loss | E26: 136.947 | F26: 18.92 | G26: 3.121 | H26: 15.799 | I26: 10 | J26: 8 | K26: 0.25 | L26: 0 | Q26: Internal | R26: 0.595 | S26: 16698.3 | T26: 3.96 | U26: 0.37291667 | Z26: 133.826 | AA26: 666.135
A27: 9 | B27: 12 | D27: Metal Loss | E27: 137.011 | F27: 18.92 | G27: 3.185 | H27: 15.735 | I27: 4 | J27: 7 | K27: 0.46 | L27: 0 | Q27: Internal | R27: 0.591 | S27: 16816 | T27: 3.96 | U27: 0.33819444 | Z27: 133.826 | AA27: 666.135
A28: 9 | B28: 13 | D28: Metal Loss | E28: 137.305 | F28: 18.92 | G28: 3.479 | H28: 15.44 | I28: 8 | J28: 10 | K28: 0.33 | L28: 0 | Q28: Internal | R28: 0.594 | S28: 16708.6 | T28: 3.96 | U28: 0.37708333 | Z28: 133.826 | AA28: 666.135
A29: 9 | B29: 14 | D29: Metal Loss | E29: 137.864 | F29: 18.92 | G29: 4.038 | H29: 14.881 | I29: 8 | J29: 10 | K29: 0.27 | L29: 0 | Q29: Internal | R29: 0.593 | S29: 16752.6 | T29: 3.96 | U29: 0.39375 | Z29: 133.826 | AA29: 666.135
A30: 9 | B30: 15 | D30: Metal Loss | E30: 139.209 | F30: 18.92 | G30: 5.383 | H30: 13.536 | I30: 10 | J30: 10 | K30: 0.29 | L30: 0 | Q30: Internal | R30: 0.596 | S30: 16656.8 | T30: 3.96 | U30: 0.16111111 | Z30: 133.826 | AA30: 666.135
A31: 9 | B31: 16 | D31: Metal Loss | E31: 139.386 | F31: 18.92 | G31: 5.56 | H31: 13.36 | I31: 16 | J31: 13 | K31: 0.27 | L31: 0 | Q31: Internal | R31: 0.606 | S31: 16397.4 | T31: 3.96 | U31: 0.24861111 | Z31: 133.826 | AA31: 666.135
A32: 9 | B32: 17 | C32: 18 | D32: Metal Loss | E32: 140.035 | F32: 18.92 | G32: 6.209 | H32: 12.711 | I32: 8 | J32: 10 | K32: 0.25 | L32: 0 | Q32: Internal | R32: 0.592 | S32: 16766 | T32: 3.96 | U32: 0.18611111 | Z32: 133.826 | AA32: 666.135
A33: 9 | B33: 18 | D33: Cluster | E33: 140.045 | F33: 18.92 | G33: 6.219 | H33: 12.701 | I33: 27.1 | J33: 13.2142 | K33: 0.27 | L33: 0 | Q33: Internal | R33: 0.628 | S33: 15812.3 | T33: 3.96 | U33: 0.18819444 | Z33: 133.826 | AA33: 666.135
A34: 9 | B34: 19 | C34: 18 | D34: Metal Loss | E34: 140.053 | F34: 18.92 | G34: 6.227 | H34: 12.693 | I34: 10 | J34: 8 | K34: 0.27 | L34: 0 | Q34: Internal | R34: 0.595 | S34: 16678 | T34: 3.96 | U34: 0.19027778 | Z34: 133.826 | AA34: 666.135
A35: 9 | B35: 20 | D35: Metal Loss | E35: 140.336 | F35: 18.92 | G35: 6.51 | H35: 12.41 | I35: 8 | J35: 8 | K35: 0.26 | L35: 0 | Q35: Internal | R35: 0.593 | S35: 16759.3 | T35: 3.96 | U35: 0.18263889 | Z35: 133.826 | AA35: 666.135
A36: 9 | B36: 21 | D36: Metal Loss | E36: 140.745 | F36: 18.92 | G36: 6.919 | H36: 12.001 | I36: 8 | J36: 10 | K36: 0.33 | L36: 0 | Q36: Internal | R36: 0.594 | S36: 16708.6 | T36: 3.96 | U36: 0.17847222 | Z36: 133.826 | AA36: 666.135
A37: 9 | B37: 22 | D37: Metal Loss | E37: 141.005 | F37: 18.92 | G37: 7.179 | H37: 11.741 | I37: 12 | J37: 10 | K37: 0.26 | L37: 0 | Q37: Internal | R37: 0.598 | S37: 16606.5 | T37: 3.96 | U37: 0.17847222 | Z37: 133.826 | AA37: 666.135
A38: 9 | B38: 23 | D38: Metal Loss | E38: 141.172 | F38: 18.92 | G38: 7.346 | H38: 11.574 | I38: 8 | J38: 8 | K38: 0.22 | L38: 0 | Q38: Internal | R38: 0.592 | S38: 16785.1 | T38: 3.96 | U38: 0.18263889 | Z38: 133.826 | AA38: 666.135
A39: 9 | B39: 24 | D39: Metal Loss | E39: 141.23 | F39: 18.92 | G39: 7.404 | H39: 11.516 | I39: 8 | J39: 10 | K39: 0.25 | L39: 0 | Q39: Internal | R39: 0.592 | S39: 16766 | T39: 3.96 | U39: 0.18680556 | Z39: 133.826 | AA39: 666.135
A40: 9 | B40: 25 | D40: Metal Loss | E40: 141.28 | F40: 18.92 | G40: 7.454 | H40: 11.466 | I40: 8 | J40: 8 | K40: 0.33 | L40: 0 | Q40: Internal | R40: 0.594 | S40: 16708.6 | T40: 3.96 | U40: 0.19097222 | Z40: 133.826 | AA40: 666.135
...

Sheet Charts-3-26 to 4-35
B2: =Header!C7 -> 3-26-68-25W5 to 4-35-68-25W5

Sheet Verifications-3-26 to 4-35
A1: Verifications
A2: Project No: | C2: 180728-RL-T6A-A | H2: Client: | I2: ARC Resources
A3: Pipeline Name: | C3: 4-35-68-25W5 to 2-26-68-25W5 | H3: Location: | I3: ValleyviewAB / Ante Creek | AE3: Imported: | AF3: P:\Data\ARC Resources\2018\Valleyview\180729-RL-T6A- 3-26 to 4-35 (28312-6)\180729-RL-T6A -A- 3-26 to 4-35\Documents\Re-Grade\180729-RL-T6A-A_PipelineListing.csv
A4: Run Date: | C4: 43310 | H4: Pipeline Segment: | I4: 3-26-68-25W5 to 4-35-68-25W5_Lic_28312-6 | Y4: Features: | Z4: 125
Y5: Joints: | Z5: 100
A6: Joint Number | B6: Feature Number | C6: Cluster Number | D6: Feature Type | E6: Distance (m) | F6: Joint Length (m) | G6: Dist to US Girth Weld (m) | H6: Dist to DS Girth Weld (m) | I6: Length (mm) | J6: Width (mm) | K6: Depth (%) | L6: Depth Measured (%) | M6: Depth Measured (mm) | N6: Difference Pred.-Meas. (%) | O6: Length Measured (mm) | P6: Width Measured (mm) | Q6: Int/Ext | R6: Estimated Repair Factor (ERF) | S6: Burst Pressure (kPa) | T6: Wall Thick (mm) | U6: Clock Position (hrs:min) | V6: % of OD Restriction | W6: Latitude (Dec Deg.) | X6: Longitude (Dec Deg.) | Y6: Elevation (m) | Z6: US Girth Weld to US Marker (m) | AA6: US Girth Weld to DS Marker (m) | AB6: Notes
A7: 1 | D7: Joint | E7: 0 | F7: 15.426 | T7: 3.96 | Z7: 0 | AA7: 799.962
A8: 1 | B8: 1 | D8: Flange | E8: 0 | F8: 15.426 | G8: 0 | H8: 15.426 | T8: 3.96 | W8: 54.911552 | X8: 117.70618 | Y8: 0 | Z8: 0 | AA8: 799.962 | AB8: Launch @ 3-26 to 4-35
A9: 1 | B9: 2 | D9: Other Installation | E9: 1.536 | F9: 15.426 | G9: 1.536 | H9: 13.89 | T9: 3.96 | Z9: 0 | AA9: 799.962 | AB9: Temporary Magnet at 12: 00
A10: 2 | D10: Joint | E10: 15.426 | F10: 7.714 | T10: 3.96 | Z10: 15.426 | AA10: 784.535
A11: 3 | D11: Joint | E11: 23.14 | F11: 16.252 | T11: 3.96 | Z11: 23.14 | AA11: 776.822
A12: 4 | D12: Joint | E12: 39.392 | F12: 18.894 | T12: 3.96 | Z12: 39.392 | AA12: 760.569
A13: 5 | D13: Joint | E13: 58.286 | F13: 18.884 | T13: 3.96 | Z13: 58.286 | AA13: 741.676
A14: 5 | B14: 3 | D14: Metal Loss | E14: 61.988 | F14: 18.884 | G14: 3.702 | H14: 15.182 | I14: 8 | J14: 10 | K14: 0.31 | L14: 0 | N14: =IF(L14=0,"",K14-L14) | Q14: Internal | R14: 0.594 | S14: 16723.9 | T14: 3.96 | U14: 0.2375 | Z14: 58.286 | AA14: 741.676
A15: 5 | B15: 4 | D15: Metal Loss | E15: 62.092 | F15: 18.884 | G15: 3.806 | H15: 15.078 | I15: 14 | J15: 10 | K15: 0.32 | L15: 0 | N15: =IF(L15=0,"",K15-L15) | Q15: Internal | R15: 0.606 | S15: 16399.6 | T15: 3.96 | U15: 0.2375 | Z15: 58.286 | AA15: 741.676
A16: 5 | B16: 5 | D16: Metal Loss | E16: 65.226 | F16: 18.884 | G16: 6.94 | H16: 11.944 | I16: 10 | J16: 10 | K16: 0.32 | L16: 0 | N16: =IF(L16=0,"",K16-L16) | Q16: Internal | R16: 0.597 | S16: 16623.3 | T16: 3.96 | U16: 0.21527778 | Z16: 58.286 | AA16: 741.676
A17: 5 | B17: 6 | C17: 7 | D17: Metal Loss | E17: 73.739 | F17: 18.884 | G17: 15.453 | H17: 3.431 | I17: 8 | J17: 8 | K17: 0.34 | L17: 0 | N17: =IF(L17=0,"",K17-L17) | Q17: Internal | R17: 0.595 | S17: 16700.7 | T17: 3.96 | U17: 0.20902778 | Z17: 58.286 | AA17: 741.676
A18: 5 | B18: 7 | D18: Cluster | E18: 73.748 | F18: 18.884 | G18: 15.462 | H18: 3.422 | I18: 25.9 | J18: 10.8612 | K18: 0.42 | L18: 0 | M18: 0 | N18: 0.42 | Q18: Internal | R18: 0.658 | S18: 15084.8 | T18: 3.96 | U18: 0.20763889 | Z18: 58.286 | AA18: 741.676
A19: 5 | B19: 8 | C19: 7 | D19: Metal Loss | E19: 73.757 | F19: 18.884 | G19: 15.471 | H19: 3.413 | I19: 8 | J19: 10 | K19: 0.42 | L19: 0 | N19: =IF(L19=0,"",K19-L19) | Q19: Internal | R19: 0.597 | S19: 16630.3 | T19: 3.96 | U19: 0.20694444 | Z19: 58.286 | AA19: 741.676
A20: 6 | D20: Joint | E20: 77.17 | F20: 18.886 | T20: 3.96 | Z20: 77.17 | AA20: 722.792
A21: 7 | D21: Joint | E21: 96.056 | F21: 18.892 | T21: 3.96 | Z21: 96.056 | AA21: 703.905
A22: 8 | D22: Joint | E22: 114.948 | F22: 18.878 | T22: 3.96 | Z22: 114.948 | AA22: 685.014
A23: 9 | D23: Joint | E23: 133.826 | F23: 18.92 | T23: 3.96 | Z23: 133.826 | AA23: 666.135
A24: 9 | B24: 9 | D24: Metal Loss | E24: 136.544 | F24: 18.92 | G24: 2.718 | H24: 16.202 | I24: 4 | J24: 8 | K24: 0.39 | L24: 0 | N24: =IF(L24=0,"",K24-L24) | Q24: Internal | R24: 0.59 | S24: 16834.2 | T24: 3.96 | U24: 0.38125 | Z24: 133.826 | AA24: 666.135
A25: 9 | B25: 10 | D25: Metal Loss | E25: 136.772 | F25: 18.92 | G25: 2.946 | H25: 15.974 | I25: 8 | J25: 6 | K25: 0.27 | L25: 0 | N25: =IF(L25=0,"",K25-L25) | Q25: Internal | R25: 0.593 | S25: 16752.6 | T25: 3.96 | U25: 0.36111111 | Z25: 133.826 | AA25: 666.135
A26: 9 | B26: 11 | D26: Metal Loss | E26: 136.947 | F26: 18.92 | G26: 3.121 | H26: 15.799 | I26: 10 | J26: 8 | K26: 0.25 | L26: 0 | N26: =IF(L26=0,"",K26-L26) | Q26: Internal | R26: 0.595 | S26: 16698.3 | T26: 3.96 | U26: 0.37291667 | Z26: 133.826 | AA26: 666.135
A27: 9 | B27: 12 | D27: Metal Loss | E27: 137.011 | F27: 18.92 | G27: 3.185 | H27: 15.735 | I27: 4 | J27: 7 | K27: 0.46 | L27: 0 | N27: =IF(L27=0,"",K27-L27) | Q27: Internal | R27: 0.591 | S27: 16816 | T27: 3.96 | U27: 0.33819444 | Z27: 133.826 | AA27: 666.135
A28: 9 | B28: 13 | D28: Metal Loss | E28: 137.305 | F28: 18.92 | G28: 3.479 | H28: 15.44 | I28: 8 | J28: 10 | K28: 0.33 | L28: 0 | N28: =IF(L28=0,"",K28-L28) | Q28: Internal | R28: 0.594 | S28: 16708.6 | T28: 3.96 | U28: 0.37708333 | Z28: 133.826 | AA28: 666.135
A29: 9 | B29: 14 | D29: Metal Loss | E29: 137.864 | F29: 18.92 | G29: 4.038 | H29: 14.881 | I29: 8 | J29: 10 | K29: 0.27 | L29: 0 | N29: =IF(L29=0,"",K29-L29) | Q29: Internal | R29: 0.593 | S29: 16752.6 | T29: 3.96 | U29: 0.39375 | Z29: 133.826 | AA29: 666.135
A30: 9 | B30: 15 | D30: Metal Loss | E30: 139.209 | F30: 18.92 | G30: 5.383 | H30: 13.536 | I30: 10 | J30: 10 | K30: 0.29 | L30: 0 | N30: =IF(L30=0,"",K30-L30) | Q30: Internal | R30: 0.596 | S30: 16656.8 | T30: 3.96 | U30: 0.16111111 | Z30: 133.826 | AA30: 666.135
A31: 9 | B31: 16 | D31: Metal Loss | E31: 139.386 | F31: 18.92 | G31: 5.56 | H31: 13.36 | I31: 16 | J31: 13 | K31: 0.27 | L31: 0 | N31: =IF(L31=0,"",K31-L31) | Q31: Internal | R31: 0.606 | S31: 16397.4 | T31: 3.96 | U31: 0.24861111 | Z31: 133.826 | AA31: 666.135
A32: 9 | B32: 17 | C32: 18 | D32: Metal Loss | E32: 140.035 | F32: 18.92 | G32: 6.209 | H32: 12.711 | I32: 8 | J32: 10 | K32: 0.25 | L32: 0 | N32: =IF(L32=0,"",K32-L32) | Q32: Internal | R32: 0.592 | S32: 16766 | T32: 3.96 | U32: 0.18611111 | Z32: 133.826 | AA32: 666.135
A33: 9 | B33: 18 | D33: Cluster | E33: 140.045 | F33: 18.92 | G33: 6.219 | H33: 12.701 | I33: 27.1 | J33: 13.2142 | K33: 0.27 | L33: 0 | M33: 0 | N33: 0.27 | Q33: Internal | R33: 0.628 | S33: 15812.3 | T33: 3.96 | U33: 0.18819444 | Z33: 133.826 | AA33: 666.135
A34: 9 | B34: 19 | C34: 18 | D34: Metal Loss | E34: 140.053 | F34: 18.92 | G34: 6.227 | H34: 12.693 | I34: 10 | J34: 8 | K34: 0.27 | L34: 0 | N34: =IF(L34=0,"",K34-L34) | Q34: Internal | R34: 0.595 | S34: 16678 | T34: 3.96 | U34: 0.19027778 | Z34: 133.826 | AA34: 666.135
A35: 9 | B35: 20 | D35: Metal Loss | E35: 140.336 | F35: 18.92 | G35: 6.51 | H35: 12.41 | I35: 8 | J35: 8 | K35: 0.26 | L35: 0 | N35: =IF(L35=0,"",K35-L35) | Q35: Internal | R35: 0.593 | S35: 16759.3 | T35: 3.96 | U35: 0.18263889 | Z35: 133.826 | AA35: 666.135
A36: 9 | B36: 21 | D36: Metal Loss | E36: 140.745 | F36: 18.92 | G36: 6.919 | H36: 12.001 | I36: 8 | J36: 10 | K36: 0.33 | L36: 0 | N36: =IF(L36=0,"",K36-L36) | Q36: Internal | R36: 0.594 | S36: 16708.6 | T36: 3.96 | U36: 0.17847222 | Z36: 133.826 | AA36: 666.135
A37: 9 | B37: 22 | D37: Metal Loss | E37: 141.005 | F37: 18.92 | G37: 7.179 | H37: 11.741 | I37: 12 | J37: 10 | K37: 0.26 | L37: 0 | N37: =IF(L37=0,"",K37-L37) | Q37: Internal | R37: 0.598 | S37: 16606.5 | T37: 3.96 | U37: 0.17847222 | Z37: 133.826 | AA37: 666.135
A38: 9 | B38: 23 | D38: Metal Loss | E38: 141.172 | F38: 18.92 | G38: 7.346 | H38: 11.574 | I38: 8 | J38: 8 | K38: 0.22 | L38: 0 | N38: =IF(L38=0,"",K38-L38) | Q38: Internal | R38: 0.592 | S38: 16785.1 | T38: 3.96 | U38: 0.18263889 | Z38: 133.826 | AA38: 666.135
A39: 9 | B39: 24 | D39: Metal Loss | E39: 141.23 | F39: 18.92 | G39: 7.404 | H39: 11.516 | I39: 8 | J39: 10 | K39: 0.25 | L39: 0 | N39: =IF(L39=0,"",K39-L39) | Q39: Internal | R39: 0.592 | S39: 16766 | T39: 3.96 | U39: 0.18680556 | Z39: 133.826 | AA39: 666.135
A40: 9 | B40: 25 | D40: Metal Loss | E40: 141.28 | F40: 18.92 | G40: 7.454 | H40: 11.466 | I40: 8 | J40: 8 | K40: 0.33 | L40: 0 | N40: =IF(L40=0,"",K40-L40) | Q40: Internal | R40: 0.594 | S40: 16708.6 | T40: 3.96 | U40: 0.19097222 | Z40: 133.826 | AA40: 666.135
...

Sheet PL-3-26 to 2-26
A1: Pipeline Listing
A2: Project No: | C2: 180729-RL-T6A-B | H2: Client: | I2: ARC Resources
A3: Pipeline Name: | C3: 4-35-68-25W5 to 2-26-68-25W5 | H3: Location: | I3: Valleyview AB / Ante Creek | AE3: Imported: | AF3: P:\Data\ARC Resources\2018\Valleyview\180729-RL-T6A- 3-26 to 4-35 (28312-6)\180729-RL-T6A-B - 3-26 to 2-26\Documents\Re-Grade\180729-RL-T6A-B_PipelineListing.csv
A4: Run Date: | C4: 43310 | H4: Pipeline Segment: | I4: 3-26-68-25W5 to 2-26-68-25W5_Lic_28312-6 | Y4: Features: | Z4: 109
Y5: Joints: | Z5: 54
A6: Joint Number | B6: Feature Number | C6: Cluster Number | D6: Feature Type | E6: Distance (m) | F6: Joint Length (m) | G6: Dist to US Girth Weld (m) | H6: Dist to DS Girth Weld (m) | I6: Length (mm) | J6: Width (mm) | K6: Depth (%) | L6: Depth Measured (%) | M6: Depth Measured (mm) | N6: Difference Pred.-Meas. (%) | O6: Length Measured (mm) | P6: Width Measured (mm) | Q6: Int/Ext | R6: Estimated Repair Factor (ERF) | S6: Burst Pressure (kPa) | T6: Wall Thick (mm) | U6: Clock Position (hrs:min) | V6: % of OD Restriction | W6: Latitude (Dec Deg.) | X6: Longitude (Dec Deg.) | Y6: Elevation (m) | Z6: US Girth Weld to US Marker (m) | AA6: US Girth Weld to DS Marker (m) | AB6: Notes
A7: 1 | D7: Joint | E7: 0 | F7: 18.252 | T7: 3.96 | Z7: 0 | AA7: 991.352
A8: 1 | B8: 1 | D8: Flange | E8: 0 | F8: 18.252 | G8: 0 | H8: 18.252 | T8: 3.96 | W8: 54.911573 | X8: 117.70589 | Y8: 0 | Z8: 0 | AA8: 991.352 | AB8: Launch at 3-26 to 2-26
A9: 1 | B9: 2 | D9: Other Installation | E9: 2.112 | F9: 18.252 | G9: 2.112 | H9: 16.14 | T9: 3.96 | Z9: 0 | AA9: 991.352 | AB9: Temporary Magnet at 12:00
A10: 1 | B10: 3 | D10: Metal Loss | E10: 16.274 | F10: 18.252 | G10: 16.274 | H10: 1.978 | I10: 8 | J10: 13 | K10: 0.27 | Q10: Internal | R10: 0.593 | S10: 16752.6 | T10: 3.96 | U10: 0.25694444 | Z10: 0 | AA10: 991.352
A11: 1 | B11: 4 | D11: Metal Loss | E11: 16.434 | F11: 18.252 | G11: 16.434 | H11: 1.818 | I11: 16 | J11: 10 | K11: 0.32 | Q11: Internal | R11: 0.61 | S11: 16275.1 | T11: 3.96 | U11: 0.24444444 | Z11: 0 | AA11: 991.352
A12: 1 | B12: 5 | D12: Metal Loss | E12: 16.606 | F12: 18.252 | G12: 16.606 | H12: 1.646 | I12: 12 | J12: 10 | K12: 0.39 | Q12: Internal | R12: 0.606 | S12: 16396.1 | T12: 3.96 | U12: 0.24444444 | Z12: 0 | AA12: 991.352
A13: 2 | D13: Joint | E13: 18.252 | F13: 18.866 | T13: 3.96 | Z13: 18.252 | AA13: 973.1
A14: 2 | B14: 6 | D14: Metal Loss | E14: 18.576 | F14: 18.866 | G14: 0.324 | H14: 18.542 | I14: 4 | J14: 15 | K14: 0.51 | Q14: Internal | R14: 0.591 | S14: 16800.6 | T14: 3.96 | U14: 0.24305556 | Z14: 18.252 | AA14: 973.1
A15: 2 | B15: 7 | D15: Metal Loss | E15: 18.866 | F15: 18.866 | G15: 0.614 | H15: 18.252 | I15: 10 | J15: 8 | K15: 0.29 | Q15: Internal | R15: 0.596 | S15: 16656.8 | T15: 3.96 | U15: 0.24652778 | Z15: 18.252 | AA15: 973.1
A16: 2 | B16: 8 | D16: Metal Loss | E16: 18.952 | F16: 18.866 | G16: 0.7 | H16: 18.166 | I16: 8 | J16: 10 | K16: 0.27 | Q16: Internal | R16: 0.593 | S16: 16752.6 | T16: 3.96 | U16: 0.25069444 | Z16: 18.252 | AA16: 973.1
A17: 2 | B17: 9 | D17: Metal Loss | E17: 18.986 | F17: 18.866 | G17: 0.734 | H17: 18.132 | I17: 20 | J17: 13 | K17: 0.35 | Q17: Internal | R17: 0.624 | S17: 15904.1 | T17: 3.96 | U17: 0.24652778 | Z17: 18.252 | AA17: 973.1
A18: 3 | D18: Joint | E18: 37.118 | F18: 19.042 | T18: 3.96 | Z18: 37.118 | AA18: 954.234
A19: 3 | B19: 10 | D19: Metal Loss | E19: 39.358 | F19: 19.042 | G19: 2.24 | H19: 16.802 | I19: 4 | J19: 15 | K19: 0.52 | Q19: Internal | R19: 0.591 | S19: 16797.3 | T19: 3.96 | U19: 0.24861111 | Z19: 37.118 | AA19: 954.234
A20: 3 | B20: 11 | D20: Metal Loss | E20: 53.942 | F20: 19.042 | G20: 16.824 | H20: 2.218 | I20: 10 | J20: 6 | K20: 0.31 | Q20: Internal | R20: 0.597 | S20: 16634.7 | T20: 3.96 | U20: 0.23333333 | Z20: 37.118 | AA20: 954.234
A21: 3 | B21: 12 | D21: Metal Loss | E21: 53.97 | F21: 19.042 | G21: 16.852 | H21: 2.19 | I21: 10 | J21: 9 | K21: 0.34 | Q21: Internal | R21: 0.598 | S21: 16599.7 | T21: 3.96 | U21: 0.23888889 | Z21: 37.118 | AA21: 954.234
A22: 4 | D22: Joint | E22: 56.16 | F22: 18.858 | T22: 3.96 | Z22: 56.16 | AA22: 935.192
A23: 4 | B23: 13 | D23: Metal Loss | E23: 68.67 | F23: 18.858 | G23: 12.51 | H23: 6.348 | I23: 10 | J23: 8 | K23: 0.28 | Q23: Internal | R23: 0.596 | S23: 16667.5 | T23: 3.96 | U23: 0.20763889 | Z23: 56.16 | AA23: 935.192
A24: 5 | D24: Joint | E24: 75.018 | F24: 18.866 | T24: 3.96 | Z24: 75.018 | AA24: 916.334
A25: 6 | D25: Joint | E25: 93.884 | F25: 18.844 | T25: 3.96 | Z25: 93.884 | AA25: 897.468
A26: 6 | B26: 14 | D26: Metal Loss | E26: 94.078 | F26: 18.844 | G26: 0.194 | H26: 18.65 | I26: 10 | J26: 6 | K26: 0.39 | Q26: Internal | R26: 0.601 | S26: 16535.9 | T26: 3.96 | U26: 0.19097222 | Z26: 93.884 | AA26: 897.468
A27: 6 | B27: 15 | D27: Metal Loss | E27: 95.366 | F27: 18.844 | G27: 1.482 | H27: 17.362 | I27: 8 | J27: 10 | K27: 0.34 | Q27: Internal | R27: 0.595 | S27: 16700.7 | T27: 3.96 | U27: 0.18888889 | Z27: 93.884 | AA27: 897.468
A28: 6 | B28: 16 | D28: Metal Loss | E28: 97.316 | F28: 18.844 | G28: 3.432 | H28: 15.412 | I28: 10 | J28: 15 | K28: 0.32 | Q28: Internal | R28: 0.597 | S28: 16623.3 | T28: 3.96 | U28: 0.25486111 | Z28: 93.884 | AA28: 897.468
A29: 6 | B29: 17 | D29: Metal Loss | E29: 97.37 | F29: 18.844 | G29: 3.486 | H29: 15.358 | I29: 8 | J29: 10 | K29: 0.32 | Q29: Internal | R29: 0.594 | S29: 16716.4 | T29: 3.96 | U29: 0.25486111 | Z29: 93.884 | AA29: 897.468
A30: 6 | B30: 18 | D30: Metal Loss | E30: 98.986 | F30: 18.844 | G30: 5.102 | H30: 13.742 | I30: 4 | J30: 6 | K30: 0.66 | Q30: Internal | R30: 0.593 | S30: 16737.1 | T30: 3.96 | U30: 0.18333333 | Z30: 93.884 | AA30: 897.468
A31: 6 | B31: 19 | D31: Metal Loss | E31: 99.022 | F31: 18.844 | G31: 5.138 | H31: 13.706 | I31: 10 | J31: 10 | K31: 0.38 | Q31: Internal | R31: 0.6 | S31: 16549.3 | T31: 3.96 | U31: 0.20555556 | Z31: 93.884 | AA31: 897.468
A32: 6 | B32: 20 | D32: Metal Loss | E32: 102.644 | F32: 18.844 | G32: 8.76 | H32: 10.084 | I32: 10 | J32: 13 | K32: 0.42 | Q32: Internal | R32: 0.602 | S32: 16493.8 | T32: 3.96 | U32: 0.20972222 | Z32: 93.884 | AA32: 897.468
A33: 6 | B33: 21 | D33: Metal Loss | E33: 110.28 | F33: 18.844 | G33: 16.396 | H33: 2.448 | I33: 4 | J33: 8 | K33: 0.35 | Q33: Internal | R33: 0.59 | S33: 16843.2 | T33: 3.96 | U33: 0.19513889 | Z33: 93.884 | AA33: 897.468
A34: 6 | B34: 22 | D34: Metal Loss | E34: 110.44 | F34: 18.844 | G34: 16.556 | H34: 2.288 | I34: 8 | J34: 10 | K34: 0.29 | Q34: Internal | R34: 0.593 | S34: 16738.6 | T34: 3.96 | U34: 0.24097222 | Z34: 93.884 | AA34: 897.468
A35: 7 | D35: Joint | E35: 112.728 | F35: 18.864 | T35: 3.96 | Z35: 112.728 | AA35: 878.624
A36: 7 | B36: 23 | D36: Metal Loss | E36: 121.742 | F36: 18.864 | G36: 9.014 | H36: 9.85 | I36: 8 | J36: 8 | K36: 0.39 | Q36: Internal | R36: 0.596 | S36: 16658.3 | T36: 3.96 | U36: 0.25416667 | Z36: 112.728 | AA36: 878.624
A37: 8 | D37: Joint | E37: 131.592 | F37: 18.88 | T37: 3.96 | Z37: 131.592 | AA37: 859.76
A38: 8 | B38: 24 | D38: Metal Loss | E38: 131.764 | F38: 18.88 | G38: 0.172 | H38: 18.708 | I38: 4 | J38: 6 | K38: 0.37 | Q38: Internal | R38: 0.59 | S38: 16838.8 | T38: 3.96 | U38: 0.24305556 | Z38: 131.592 | AA38: 859.76
A39: 8 | B39: 25 | D39: Metal Loss | E39: 140.364 | F39: 18.88 | G39: 8.772 | H39: 10.108 | I39: 8 | J39: 6 | K39: 0.36 | Q39: Internal | R39: 0.595 | S39: 16684.4 | T39: 3.96 | U39: 0.24444444 | Z39: 131.592 | AA39: 859.76
A40: 8 | B40: 26 | D40: Metal Loss | E40: 142.238 | F40: 18.88 | G40: 10.646 | H40: 8.234 | I40: 8 | J40: 6 | K40: 0.27 | Q40: Internal | R40: 0.593 | S40: 16752.6 | T40: 3.96 | U40: 0.23680556 | Z40: 131.592 | AA40: 859.76
...

Sheet Charts-3-26 to 2-26
B2: =Header!C8 -> 3-26-68-25W5 to 2-26-68-25W5

Sheet Verifications-3-26 to 2-26
A1: Verifications
A2: Project No: | C2: 180729-RL-T6A-B | H2: Client: | I2: ARC Resources
A3: Pipeline Name: | C3: 4-35-68-25W5 to 2-26-68-25W5 | H3: Location: | I3: Valleyview AB / Ante Creek | AJ3: Imported: | AK3: P:\Data\ARC Resources\2018\Valleyview\180729-RL-T6A- 3-26 to 4-35 (28312-6)\180729-RL-T6A-B - 3-26 to 2-26\Documents\Re-Grade\180729-RL-T6A-B_PipelineListing.csv
A4: Run Date: | C4: 43310 | H4: Pipeline Segment: | I4: 3-26-68-25W5 to 2-26-68-25W5_Lic_28312-6 | AD4: Features: | AE4: 109
AD5: Joints: | AE5: 54
A6: Joint Number | B6: Feature Number | C6: Cluster Number | D6: Feature Type | E6: Distance (m) | F6: Joint Length (m) | G6: Dist to US Girth Weld (m) | H6: Dist to DS Girth Weld (m) | I6: Length (mm) | J6: Width (mm) | K6: Depth (%) | L6: Depth Measured (%) | M6: Depth Measured (mm) | N6: Difference Pred.-Meas. (%) | O6: Length Measured (mm) | P6: Width Measured (mm) | Q6: Previous Depth (%) | R6: Depth Diff (%) | S6: Previous Distance (m) | T6: Previous Joint Number | U6: Previous Joint Distance (m) | V6: Int/Ext | W6: Estimated Repair Factor (ERF) | X6: Burst Pressure (kPa) | Y6: Wall Thick (mm) | Z6: Clock Position (hrs:min) | AA6: % of OD Restriction | AB6: Latitude (Dec Deg.) | AC6: Longitude (Dec Deg.) | AD6: Elevation (m) | AE6: US Girth Weld to US Marker (m) | AF6: US Girth Weld to DS Marker (m) | AG6: Notes
A7: 1 | D7: Joint | E7: 0 | F7: 18.252 | Y7: 3.96 | AE7: 0 | AF7: 991.352
A8: 1 | B8: 1 | D8: Flange | E8: 0 | F8: 18.252 | G8: 0 | H8: 18.252 | Y8: 3.96 | AB8: 54.911573 | AC8: 117.70589 | AD8: 0 | AE8: 0 | AF8: 991.352 | AG8: Launch at 3-26 to 2-26
A9: 1 | B9: 2 | D9: Other Installation | E9: 2.112 | F9: 18.252 | G9: 2.112 | H9: 16.14 | Y9: 3.96 | AE9: 0 | AF9: 991.352 | AG9: Temporary Magnet at 12:00
A10: 1 | B10: 3 | D10: Metal Loss | E10: 16.274 | F10: 18.252 | G10: 16.274 | H10: 1.978 | I10: 8 | J10: 13 | K10: 0.27 | V10: Internal | W10: 0.593 | X10: 16752.6 | Y10: 3.96 | Z10: 0.25694444 | AE10: 0 | AF10: 991.352
A11: 1 | B11: 4 | D11: Metal Loss | E11: 16.434 | F11: 18.252 | G11: 16.434 | H11: 1.818 | I11: 16 | J11: 10 | K11: 0.32 | V11: Internal | W11: 0.61 | X11: 16275.1 | Y11: 3.96 | Z11: 0.24444444 | AE11: 0 | AF11: 991.352
A12: 1 | B12: 5 | D12: Metal Loss | E12: 16.606 | F12: 18.252 | G12: 16.606 | H12: 1.646 | I12: 12 | J12: 10 | K12: 0.39 | V12: Internal | W12: 0.606 | X12: 16396.1 | Y12: 3.96 | Z12: 0.24444444 | AE12: 0 | AF12: 991.352
A13: 2 | D13: Joint | E13: 18.252 | F13: 18.866 | Y13: 3.96 | AE13: 18.252 | AF13: 973.1
A14: 2 | B14: 6 | D14: Metal Loss | E14: 18.576 | F14: 18.866 | G14: 0.324 | H14: 18.542 | I14: 4 | J14: 15 | K14: 0.51 | V14: Internal | W14: 0.591 | X14: 16800.6 | Y14: 3.96 | Z14: 0.24305556 | AE14: 18.252 | AF14: 973.1
A15: 2 | B15: 7 | D15: Metal Loss | E15: 18.866 | F15: 18.866 | G15: 0.614 | H15: 18.252 | I15: 10 | J15: 8 | K15: 0.29 | V15: Internal | W15: 0.596 | X15: 16656.8 | Y15: 3.96 | Z15: 0.24652778 | AE15: 18.252 | AF15: 973.1
A16: 2 | B16: 8 | D16: Metal Loss | E16: 18.952 | F16: 18.866 | G16: 0.7 | H16: 18.166 | I16: 8 | J16: 10 | K16: 0.27 | V16: Internal | W16: 0.593 | X16: 16752.6 | Y16: 3.96 | Z16: 0.25069444 | AE16: 18.252 | AF16: 973.1
A17: 2 | B17: 9 | D17: Metal Loss | E17: 18.986 | F17: 18.866 | G17: 0.734 | H17: 18.132 | I17: 20 | J17: 13 | K17: 0.35 | V17: Internal | W17: 0.624 | X17: 15904.1 | Y17: 3.96 | Z17: 0.24652778 | AE17: 18.252 | AF17: 973.1
A18: 3 | D18: Joint | E18: 37.118 | F18: 19.042 | Y18: 3.96 | AE18: 37.118 | AF18: 954.234
A19: 3 | B19: 10 | D19: Metal Loss | E19: 39.358 | F19: 19.042 | G19: 2.24 | H19: 16.802 | I19: 4 | J19: 15 | K19: 0.52 | V19: Internal | W19: 0.591 | X19: 16797.3 | Y19: 3.96 | Z19: 0.24861111 | AE19: 37.118 | AF19: 954.234
A20: 3 | B20: 11 | D20: Metal Loss | E20: 53.942 | F20: 19.042 | G20: 16.824 | H20: 2.218 | I20: 10 | J20: 6 | K20: 0.31 | V20: Internal | W20: 0.597 | X20: 16634.7 | Y20: 3.96 | Z20: 0.23333333 | AE20: 37.118 | AF20: 954.234
A21: 3 | B21: 12 | D21: Metal Loss | E21: 53.97 | F21: 19.042 | G21: 16.852 | H21: 2.19 | I21: 10 | J21: 9 | K21: 0.34 | V21: Internal | W21: 0.598 | X21: 16599.7 | Y21: 3.96 | Z21: 0.23888889 | AE21: 37.118 | AF21: 954.234
A22: 4 | D22: Joint | E22: 56.16 | F22: 18.858 | Y22: 3.96 | AE22: 56.16 | AF22: 935.192
A23: 4 | B23: 13 | D23: Metal Loss | E23: 68.67 | F23: 18.858 | G23: 12.51 | H23: 6.348 | I23: 10 | J23: 8 | K23: 0.28 | V23: Internal | W23: 0.596 | X23: 16667.5 | Y23: 3.96 | Z23: 0.20763889 | AE23: 56.16 | AF23: 935.192
A24: 5 | D24: Joint | E24: 75.018 | F24: 18.866 | Y24: 3.96 | AE24: 75.018 | AF24: 916.334
A25: 6 | D25: Joint | E25: 93.884 | F25: 18.844 | Y25: 3.96 | AE25: 93.884 | AF25: 897.468
A26: 6 | B26: 14 | D26: Metal Loss | E26: 94.078 | F26: 18.844 | G26: 0.194 | H26: 18.65 | I26: 10 | J26: 6 | K26: 0.39 | V26: Internal | W26: 0.601 | X26: 16535.9 | Y26: 3.96 | Z26: 0.19097222 | AE26: 93.884 | AF26: 897.468
A27: 6 | B27: 15 | D27: Metal Loss | E27: 95.366 | F27: 18.844 | G27: 1.482 | H27: 17.362 | I27: 8 | J27: 10 | K27: 0.34 | V27: Internal | W27: 0.595 | X27: 16700.7 | Y27: 3.96 | Z27: 0.18888889 | AE27: 93.884 | AF27: 897.468
A28: 6 | B28: 16 | D28: Metal Loss | E28: 97.316 | F28: 18.844 | G28: 3.432 | H28: 15.412 | I28: 10 | J28: 15 | K28: 0.32 | V28: Internal | W28: 0.597 | X28: 16623.3 | Y28: 3.96 | Z28: 0.25486111 | AE28: 93.884 | AF28: 897.468
A29: 6 | B29: 17 | D29: Metal Loss | E29: 97.37 | F29: 18.844 | G29: 3.486 | H29: 15.358 | I29: 8 | J29: 10 | K29: 0.32 | V29: Internal | W29: 0.594 | X29: 16716.4 | Y29: 3.96 | Z29: 0.25486111 | AE29: 93.884 | AF29: 897.468
A30: 6 | B30: 18 | D30: Metal Loss | E30: 98.986 | F30: 18.844 | G30: 5.102 | H30: 13.742 | I30: 4 | J30: 6 | K30: 0.66 | V30: Internal | W30: 0.593 | X30: 16737.1 | Y30: 3.96 | Z30: 0.18333333 | AE30: 93.884 | AF30: 897.468
A31: 6 | B31: 19 | D31: Metal Loss | E31: 99.022 | F31: 18.844 | G31: 5.138 | H31: 13.706 | I31: 10 | J31: 10 | K31: 0.38 | V31: Internal | W31: 0.6 | X31: 16549.3 | Y31: 3.96 | Z31: 0.20555556 | AE31: 93.884 | AF31: 897.468
A32: 6 | B32: 20 | D32: Metal Loss | E32: 102.644 | F32: 18.844 | G32: 8.76 | H32: 10.084 | I32: 10 | J32: 13 | K32: 0.42 | V32: Internal | W32: 0.602 | X32: 16493.8 | Y32: 3.96 | Z32: 0.20972222 | AE32: 93.884 | AF32: 897.468
A33: 6 | B33: 21 | D33: Metal Loss | E33: 110.28 | F33: 18.844 | G33: 16.396 | H33: 2.448 | I33: 4 | J33: 8 | K33: 0.35 | V33: Internal | W33: 0.59 | X33: 16843.2 | Y33: 3.96 | Z33: 0.19513889 | AE33: 93.884 | AF33: 897.468
A34: 6 | B34: 22 | D34: Metal Loss | E34: 110.44 | F34: 18.844 | G34: 16.556 | H34: 2.288 | I34: 8 | J34: 10 | K34: 0.29 | V34: Internal | W34: 0.593 | X34: 16738.6 | Y34: 3.96 | Z34: 0.24097222 | AE34: 93.884 | AF34: 897.468
A35: 7 | D35: Joint | E35: 112.728 | F35: 18.864 | Y35: 3.96 | AE35: 112.728 | AF35: 878.624
A36: 7 | B36: 23 | D36: Metal Loss | E36: 121.742 | F36: 18.864 | G36: 9.014 | H36: 9.85 | I36: 8 | J36: 8 | K36: 0.39 | V36: Internal | W36: 0.596 | X36: 16658.3 | Y36: 3.96 | Z36: 0.25416667 | AE36: 112.728 | AF36: 878.624
A37: 8 | D37: Joint | E37: 131.592 | F37: 18.88 | Y37: 3.96 | AE37: 131.592 | AF37: 859.76
A38: 8 | B38: 24 | D38: Metal Loss | E38: 131.764 | F38: 18.88 | G38: 0.172 | H38: 18.708 | I38: 4 | J38: 6 | K38: 0.37 | V38: Internal | W38: 0.59 | X38: 16838.8 | Y38: 3.96 | Z38: 0.24305556 | AE38: 131.592 | AF38: 859.76
A39: 8 | B39: 25 | D39: Metal Loss | E39: 140.364 | F39: 18.88 | G39: 8.772 | H39: 10.108 | I39: 8 | J39: 6 | K39: 0.36 | V39: Internal | W39: 0.595 | X39: 16684.4 | Y39: 3.96 | Z39: 0.24444444 | AE39: 131.592 | AF39: 859.76
A40: 8 | B40: 26 | D40: Metal Loss | E40: 142.238 | F40: 18.88 | G40: 10.646 | H40: 8.234 | I40: 8 | J40: 6 | K40: 0.27 | V40: Internal | W40: 0.593 | X40: 16752.6 | Y40: 3.96 | Z40: 0.23680556 | AE40: 131.592 | AF40: 859.76
...

Sheet ML v Elevation
B2: =Header!C7 -> 3-26-68-25W5 to 4-35-68-25W5 | O2: =Header!C8 -> 3-26-68-25W5 to 2-26-68-25W5

Sheet Google Earth Elevation Profile
B2: =Header!C7 -> 3-26-68-25W5 to 4-35-68-25W5 | Q2: =Header!C8 -> 3-26-68-25W5 to 2-26-68-25W5

Sheet Google Earth Map 
